<?xml version="1.0"?>
<robot name="myfirst">
  <material name="red">
    <color rgba="0.8 0.0 0.0 1"/>
  </material>
  <material name="blue">
    <color rgba="0.0 0.0 0.8 1"/>
  </material>
  <material name="green">
    <color rgba="0.0 0.8 0.0 1"/>
  </material>
  <material name="purple">
    <color rgba="0.576 0.439 0.859 1"/>
  </material>
  <material name="orange">
    <color rgba="1.0 0.580 0.439 1"/>
  </material>
  <material name="yellow">
    <color rgba="1.0 0.941 0.0 1"/>
  </material>
  <material name="white">
    <color rgba="1.0 1.0 1.0 1"/>
  </material>

  <link name="base_link">
    <visual>
      <geometry>
        <cylinder length="0.033829" radius="0.023"/>
      </geometry>
      <material name="red"/>
    </visual>
  </link>

  <link name="base_connector">
    <visual>
      <geometry>
        <box size="0.0671 0.035 0.005"/>
      </geometry>
      <origin rpy="0 0 0" xyz="0.023 0 0"/>
      <material name="red"/>
    </visual>
  </link>

  <link name="second_link">
    <visual>
      <geometry>
        <cylinder length="0.033829" radius="0.023"/>
      </geometry>
      <material name="blue"/>
    </visual>
  </link>

  <link name="second_connector">
    <visual>
      <geometry>
        <cylinder length="0.139" radius="0.018"/>
      </geometry>
      <origin rpy="0 0 0" xyz="0.053 0 -0.063"/>
      <material name="blue"/>
    </visual>
  </link>

  <link name="third_link">
    <visual>
      <geometry>
        <cylinder length="0.033829" radius="0.023"/>
      </geometry>
      <material name="green"/>
    </visual>
  </link>

  <link name="third_connector">
    <visual>
      <geometry>
        <cylinder length="0.109" radius="0.018"/>
      </geometry>
      <origin rpy="0 0 0" xyz="0.033 0 -0.043"/>
      <material name="green"/>
    </visual>
  </link>

  <link name="fourth_link">
    <visual>
      <geometry>
        <cylinder length="0.033829" radius="0.023"/>
      </geometry>
      <material name="purple"/>
    </visual>
  </link>

  <link name="fifth_link">
    <visual>
      <geometry>
        <cylinder length="0.033829" radius="0.023"/>
      </geometry>
      <material name="orange"/>
    </visual>
  </link>

  <link name="sixth_link">
    <visual>
      <geometry>
        <cylinder length="0.033829" radius="0.023"/>
      </geometry>
      <material name="yellow"/>
    </visual>
  </link>

  <link name="hand_extension">
    <visual>
      <geometry>
        <box size="0.015 0.015 0.015"/>
      </geometry>
      <material name="white"/>
    </visual>
  </link>

  <joint name="base_axis" type="revolute">
    <parent link="base_link"/>
    <child link="base_connector"/>
    <limit lower="0" upper="6.283" effort="30" velocity="1"/>
    <axis xyz="0 0 1"/>
    <origin rpy="0 0 0" xyz="0 0 0.0205"/>
  </joint>

  <joint name="base_axis_end" type="fixed">
    <parent link="base_connector"/>
    <child link="second_link"/>
    <origin rpy="1.57 0 0" xyz="0.040 0 0.0205"/>
  </joint>

  <joint name="second_axis" type="revolute">
    <parent link="second_link"/>
    <child link="second_connector"/>
    <limit lower="0" upper="6.283" effort="30" velocity="1"/>
    <axis xyz="1 0 0"/>
    <origin rpy="0 1.57 0" xyz="0 0 0.0205"/>
  </joint>

  <joint name="second_axis_end" type="fixed">
    <parent link="second_connector"/>
    <child link="third_link"/>
    <origin rpy="0 1.57 0" xyz="0.023 0 -0.126"/>
  </joint>

  <joint name="third_axis" type="revolute">
    <parent link="third_link"/>
    <child link="third_connector"/>
    <limit lower="0" upper="6.283" effort="30" velocity="1"/>
    <axis xyz="1 0 0"/>
    <origin rpy="0 1.57 0" xyz="0.0 0 0.0"/>
  </joint>

  <joint name="third_axis_end" type="fixed">
    <parent link="third_connector"/>
    <child link="fourth_link"/>
    <origin rpy="0 1.57 0" xyz="0.033 0 -0.116"/>
  </joint>

  <joint name="fourth_axis" type="revolute">
    <parent link="fourth_link"/>
    <child link="fifth_link"/>
    <limit lower="0" upper="6.283" effort="30" velocity="1"/>
    <axis xyz="1 0 0"/>
    <origin rpy="0 1.57 0" xyz="0 0 -0.0378"/>
  </joint>

  <joint name="fifth_axis" type="revolute">
    <parent link="fifth_link"/>
    <child link="sixth_link"/>
    <limit lower="0" upper="6.283" effort="30" velocity="1"/>
    <axis xyz="1 0 0"/>
    <origin rpy="0 1.57 0" xyz="0 0 -0.0378"/>
  </joint>

  <joint name="sixth_axis" type="revolute">
    <parent link="sixth_link"/>
    <child link="hand_extension"/>
    <limit lower="0" upper="6.283" effort="30" velocity="1"/>
    <axis xyz="1 0 0"/>
    <origin rpy="0 0 0" xyz="0 0 -0.0378"/>
  </joint>
</robot>
