<?xml version="1.0" ?>
<!-- =================================================================================== -->
<!-- |    This document was autogenerated by xacro from arm_model.xacro                | -->
<!-- |    EDITING THIS FILE BY HAND IS NOT RECOMMENDED                                 | -->
<!-- =================================================================================== -->
<robot name="robot-arm">
  <!--- Materials to differentiate between joints -->
  <material name="purple">
    <color rgba="0.576 0.439 0.859 1"/>
  </material>
  <material name="yellow">
    <color rgba="1.0 0.941 0.0 1"/>
  </material>
  <link name="world"/>
  <link name="joint_1">
    <collision>
      <geometry>
        <cylinder length="0.0645" radius="0.0459"/>
      </geometry>
    </collision>
    <visual>
      <geometry>
        <cylinder length="0.0645" radius="0.0459"/>
      </geometry>
      <material name="yellow"/>
    </visual>
    <inertial>
      <mass value="0.69"/>
      <inertia ixx="0.0006026391" ixy="0.0" ixz="0.0" iyy="0.0006026391" iyz="0.0" izz="0.00072684945"/>
    </inertial>
  </link>
  <link name="joint_2">
    <collision>
      <geometry>
        <cylinder length="0.0645" radius="0.0459"/>
      </geometry>
    </collision>
    <visual>
      <geometry>
        <cylinder length="0.0645" radius="0.0459"/>
      </geometry>
      <material name="yellow"/>
    </visual>
    <inertial>
      <mass value="0.69"/>
      <inertia ixx="0.0006026391" ixy="0.0" ixz="0.0" iyy="0.0006026391" iyz="0.0" izz="0.00072684945"/>
    </inertial>
  </link>
  <link name="joint_3">
    <collision>
      <geometry>
        <cylinder length="0.0645" radius="0.0459"/>
      </geometry>
    </collision>
    <visual>
      <geometry>
        <cylinder length="0.0645" radius="0.0459"/>
      </geometry>
      <material name="yellow"/>
    </visual>
    <inertial>
      <mass value="0.69"/>
      <inertia ixx="0.0006026391" ixy="0.0" ixz="0.0" iyy="0.0006026391" iyz="0.0" izz="0.00072684945"/>
    </inertial>
  </link>
  <link name="joint_4">
    <collision>
      <geometry>
        <cylinder length="0.03935" radius="0.0459"/>
      </geometry>
    </collision>
    <visual>
      <geometry>
        <cylinder length="0.03935" radius="0.0459"/>
      </geometry>
      <material name="yellow"/>
    </visual>
    <inertial>
      <mass value="0.69"/>
      <inertia ixx="0.00045245901875" ixy="0.0" ixz="0.0" iyy="0.00045245901875" iyz="0.0" izz="0.00072684945"/>
    </inertial>
  </link>
  <link name="joint_5">
    <collision>
      <geometry>
        <cylinder length="0.03935" radius="0.0459"/>
      </geometry>
    </collision>
    <visual>
      <geometry>
        <cylinder length="0.03935" radius="0.0459"/>
      </geometry>
      <material name="yellow"/>
    </visual>
    <inertial>
      <mass value="0.69"/>
      <inertia ixx="0.00045245901875" ixy="0.0" ixz="0.0" iyy="0.00045245901875" iyz="0.0" izz="0.00072684945"/>
    </inertial>
  </link>
  <link name="joint_6">
    <collision>
      <geometry>
        <cylinder length="0.03935" radius="0.0459"/>
      </geometry>
    </collision>
    <visual>
      <geometry>
        <cylinder length="0.03935" radius="0.0459"/>
      </geometry>
      <material name="yellow"/>
    </visual>
    <inertial>
      <mass value="0.69"/>
      <inertia ixx="0.00045245901875" ixy="0.0" ixz="0.0" iyy="0.00045245901875" iyz="0.0" izz="0.00072684945"/>
    </inertial>
  </link>
  <link name="link_23">
    <collision>
      <geometry>
        <cylinder length="0.1941" radius="0.030163"/>
      </geometry>
    </collision>
    <visual>
      <geometry>
        <cylinder length="0.1941" radius="0.030163"/>
      </geometry>
      <material name="purple"/>
    </visual>
    <inertial>
      <mass value="0.69"/>
      <inertia ixx="0.0033670191422499993" ixy="0.0" ixz="0.0" iyy="0.0033670191422499993" iyz="0.0" izz="0.00045490328449999994"/>
    </inertial>
  </link>
  <link name="link_34">
    <collision>
      <geometry>
        <cylinder length="0.1941" radius="0.030163"/>
      </geometry>
    </collision>
    <visual>
      <geometry>
        <cylinder length="0.1941" radius="0.030163"/>
      </geometry>
      <material name="purple"/>
    </visual>
    <inertial>
      <mass value="0.69"/>
      <inertia ixx="0.0033670191422499993" ixy="0.0" ixz="0.0" iyy="0.0033670191422499993" iyz="0.0" izz="0.00045490328449999994"/>
    </inertial>
  </link>
  <!--- End-Effector which is a box rn (colored purple) -->
  <link name="end_effector">
    <collision>
      <geometry>
        <box size="0.02 0.02 0.05"/>
      </geometry>
    </collision>
    <visual>
      <geometry>
        <box size="0.02 0.02 0.05"/>
      </geometry>
      <material name="purple"/>
    </visual>
    <inertial>
      <mass value="1.0"/>
      <inertia ixx="0.0029000000000000007" ixy="0.0" ixz="0.0" iyy="0.0029000000000000007" iyz="0.0" izz="0.0008"/>
    </inertial>
  </link>
  <joint name="axis_1" type="revolute">
    <parent link="world"/>
    <child link="joint_1"/>
    <limit effort="30" lower="0.0" upper="6.283185307179586" velocity="1"/>
    <axis xyz="0 0 1"/>
    <origin rpy="0.0 0.0 0" xyz="0.0 0 0.05"/>
  </joint>
  <joint name="axis_2" type="revolute">
    <parent link="joint_1"/>
    <child link="joint_2"/>
    <limit effort="30" lower="-3.141592653589793" upper="3.141592653589793" velocity="1"/>
    <axis xyz="0 0 1"/>
    <origin rpy="-1.5707963267948966 0 0" xyz="0.067114 0 0.069829"/>
  </joint>
  <joint name="axis_3" type="revolute">
    <parent link="joint_2"/>
    <child link="joint_3"/>
    <limit effort="30" lower="-3.141592653589793" upper="3.141592653589793" velocity="1"/>
    <axis xyz="0 0 1"/>
    <origin rpy="3.141592653589793 0 -1.5707963267948966" xyz="0 -0.209509 0.070162"/>
  </joint>
  <joint name="link_to_joint_2" type="fixed">
    <parent link="joint_2"/>
    <child link="link_23"/>
    <limit effort="30" lower="-3.141592653589793" upper="3.141592653589793" velocity="1"/>
    <origin rpy="1.5707963267948966 0 0" xyz="0 -0.09705 0.070162"/>
  </joint>
  <joint name="axis_4" type="revolute">
    <parent link="joint_3"/>
    <child link="joint_4"/>
    <limit effort="30" lower="0" upper="6.283185307179586" velocity="1"/>
    <axis xyz="0 0 1"/>
    <origin rpy="-3.141592653589793 0 1.5707963267948966" xyz="0 0.18 0"/>
  </joint>
  <joint name="link_to_joint_3" type="fixed">
    <parent link="joint_3"/>
    <child link="link_34"/>
    <limit effort="30" lower="-3.141592653589793" upper="3.141592653589793" velocity="1"/>
    <origin rpy="1.5707963267948966 0 0" xyz="0 0.1075 0.0645"/>
  </joint>
  <joint name="axis_5" type="revolute">
    <parent link="joint_4"/>
    <child link="joint_5"/>
    <limit effort="30" lower="-3.141592653589793" upper="3.141592653589793" velocity="1"/>
    <axis xyz="0 0 1"/>
    <origin rpy="-1.5707963267948966 0 0" xyz="0 0 0.082409"/>
  </joint>
  <joint name="axis_6" type="revolute">
    <parent link="joint_5"/>
    <child link="joint_6"/>
    <limit effort="30" lower="-3.141592653589793" upper="3.141592653589793" velocity="1"/>
    <axis xyz="0 0 1"/>
    <origin rpy="1.5707963267948966 0 -1.5707963267948966" xyz="0 0 0.0831"/>
  </joint>
  <joint name="joint_transform_6" type="fixed">
    <parent link="joint_6"/>
    <child link="end_effector"/>
    <limit effort="30" lower="-3.141592653589793" upper="3.141592653589793" velocity="1"/>
    <axis xyz="0 0 1"/>
    <origin rpy="0 0 0" xyz="0 0 0.05"/>
  </joint>
  <transmission name="axis_1_trans">
    <type>transmission_interface/SimpleTransmission</type>
    <acutator name="axis_1_motor">
      <hardwareInterface>hardware_interface/EffortJointInterface</hardwareInterface>
      <mechanicalReduction> 1 </mechanicalReduction>
    </acutator>
    <joint name="axis_1">
      <hardwareInterface>hardware_interface/EffortJointInterface</hardwareInterface>
    </joint>
  </transmission>
  <gazebo>
    <plugin filename="libgazebo_ros_control.so" name="gazebo_ros_control">
      <robotNamespace>/arm_robot</robotNamespace>
    </plugin>
  </gazebo>
</robot>

